Workbook

Sheet Valuation Assumptions
B2: Assumptions - DCF | G2: Wacc | I2: =(I9*I10)+(I4*I5*(1-I6)) -> 0.0909864 | K2: Revenue Projections
B3: Terminal Growth | D3: 0.025 | G3: Debt | I3: 52623 | K3: 2015 | L3: 2016 | M3: 2017 | N3: 2018 | O3: 2019 | P3: 2020 | Q3: 2021 | R3: 2022 | S3: 2023 | T3: 2024 | U3: Forecast | V3: 2025 | W3: 2026 | X3: 2027 | Y3: 2028 | Z3: 2029
B4: Depreciation | D4: 0.03 | G4: % Debt | I4: 0.022 | K4: 107006 | L4: 135987 | M4: 177866 | N4: 232887 | O4: 280522 | P4: 386064 | Q4: 469822 | R4: 513983 | S4: 574785 | T4: 637959 | U4: Upside | V4: =T4*(1+D12) -> 708134.49 | W4: =V4*(1+D12) -> 786029.28 | X4: =W4*(1+D12) -> 872492.51 | Y4: =X4*(1+D12) -> 968466.68 | Z4: =Y4*(1+D12) -> 1074998
B5: Capital Expenditures | D5: 0.15 | G5: Cost of Debt | I5: 0.03 | U5: Downside | V5: =T4*(1+D13) -> 663477.36 | W5: =V5*(1+D13) -> 690016.45 | X5: =W5*(1+D13) -> 717617.11 | Y5: =X5*(1+D13) -> 746321.8 | Z5: =Y5*(1+D13) -> 776174.67
B6: Change in NWC | D6: 0 | G6: Tax Rate | I6: 0.21
B7: Tax Rate | D7: 0.17
G8: Market Equity Value | I8: 2323998
B9: Assumptions - Exit Multiple | G9: % Equity | I9: 0.978
B10: Upside P/E | D10: 35 | G10: Cost of Equity | I10: =I11+I12*I13 -> 0.0925
B11: Downside P/E | D11: 25 | G11: Risk Free Rate | I11: 0.03
B12: Upside Growth Rate | D12: 0.11 | G12: Beta | I12: 1.25
B13: Downside Growth Rate | D13: 0.04 | G13: Market Risk Premium | I13: 0.05
A15: All dollar figures in USD millions unless otherwise stated.

Sheet DCF
C2: Upside Case | F2: FY 2015 | G2: FY 2016 | H2: FY 2017 | I2: FY 2018 | J2: FY 2019 | K2: FY 2020 | L2: FY 2021 | M2: FY 2022 | N2: FY 2023 | O2: FY 2024 | P2: FY 2025 | Q2: FY 2026 | R2: FY 2027 | S2: FY 2028 | T2: FY 2029
C3: Revenue | F3: ='Exit Multiple'!C3 -> 107006 | G3: ='Exit Multiple'!D3 -> 135987 | H3: ='Exit Multiple'!E3 -> 177866 | I3: ='Exit Multiple'!F3 -> 232887 | J3: ='Exit Multiple'!G3 -> 280522 | K3: ='Exit Multiple'!H3 -> 386064 | L3: ='Exit Multiple'!I3 -> 469822 | M3: ='Exit Multiple'!J3 -> 513983 | ... T3: ='Exit Multiple'!Q3 -> 1074998
C4: % of Growth | G4: =(G3-F3)/F3 -> 0.27083528 | H4: =(H3-G3)/G3 -> 0.30796326 | I4: =(I3-H3)/H3 -> 0.30933962 | J4: =(J3-I3)/I3 -> 0.20454126 | K4: =(K3-J3)/J3 -> 0.37623431 | L4: =(L3-K3)/K3 -> 0.21695367 | M4: =(M3-L3)/L3 -> 0.093995173 | N4: =(N3-M3)/M3 -> 0.11829574 | ... T4: =(T3-S3)/S3 -> 0.11
C6: EBIT | F6: ='Exit Multiple'!C7 -> 2233 | G6: ='Exit Multiple'!D7 -> 4186 | H6: ='Exit Multiple'!E7 -> 4106 | I6: ='Exit Multiple'!F7 -> 12421 | J6: ='Exit Multiple'!G7 -> 14541 | K6: ='Exit Multiple'!H7 -> 22899 | L6: ='Exit Multiple'!I7 -> 24879 | M6: ='Exit Multiple'!J7 -> 12248 | ... T6: ='Exit Multiple'!Q7 -> 106085.95
C7: % of Sales | F7: =F6/F3 -> 0.020867989 | G7: =G6/G3 -> 0.030782354 | H7: =H6/H3 -> 0.023084794 | I7: =I6/I3 -> 0.053334879 | J7: =J6/J3 -> 0.051835507 | K7: =K6/K3 -> 0.059314 | L7: =L6/L3 -> 0.052954098 | M7: =M6/M3 -> 0.023829582 | ... T7: =T6/T3 -> 0.098684791
C9: Taxes | F9: 950 | G9: 1425 | H9: 769 | I9: 1197 | J9: 2374 | K9: 2863 | L9: 4791 | M9: 3217 | N9: 7120 | O9: 9265 | P9: ='Exit Multiple'!M11 -> 11850.15 | Q9: ='Exit Multiple'!N11 -> 13138.983 | R9: ='Exit Multiple'!O11 -> 14569.587 | S9: ='Exit Multiple'!P11 -> 16157.557 | T9: ='Exit Multiple'!Q11 -> 17920.204
C10: % of EBIT | F10: =F9/F6 -> 0.42543663 | G10: =G9/G6 -> 0.34042045 | H10: =H9/H6 -> 0.1872869 | I10: =I9/I6 -> 0.096369052 | J10: =J9/J6 -> 0.1632625 | K10: =K9/K6 -> 0.12502729 | L10: =L9/L6 -> 0.19257205 | M10: =M9/M6 -> 0.26265513 | ... T10: =T9/T6 -> 0.16892155
C12: EBIAT | F12: =F6-F9 -> 1283 | G12: =G6-G9 -> 2761 | H12: =H6-H9 -> 3337 | I12: =I6-I9 -> 11224 | J12: =J6-J9 -> 12167 | K12: =K6-K9 -> 20036 | L12: =L6-L9 -> 20088 | M12: =M6-M9 -> 9031 | ... T12: =T6-T9 -> 88165.751
C14: Depreciation | F14: 6281 | G14: 8116 | H14: 11478 | I14: 15341 | J14: 21789 | K14: 25180 | L14: 34433 | M14: 41921 | N14: 48663 | O14: 52795 | P14: =P3*W15 -> 50557.239 | Q14: =Q3*W15 -> 56118.535 | R14: =R3*W15 -> 62291.574 | S14: =S3*W15 -> 69143.647 | T14: =T3*W15 -> 76749.449
C15: % of Revenue | F15: =F14/F3 -> 0.058697643 | G15: =G14/G3 -> 0.059682176 | H15: =H14/H3 -> 0.064531726 | I15: =I14/I3 -> 0.065873149 | J15: =J14/J3 -> 0.077673052 | K15: =K14/K3 -> 0.065222347 | L15: =L14/L3 -> 0.073289459 | M15: =M14/M3 -> 0.081561063 | ... O15: =O14/O3 -> 0.082756102 | P15: 0.0714 | Q15: 0.0714 | R15: 0.0714 | S15: 0.0714 | T15: 0.0714 | V15: Average | W15: =AVERAGE(F15:O15) -> 0.071394968
C17: CapEx | F17: 5387 | G17: 7804 | H17: 11955 | I17: 13427 | J17: 16861 | K17: 40140 | L17: 61053 | M17: 63645 | N17: 52729 | O17: 82999 | P17: =P3*W18 -> 61769.943 | Q17: =Q3*W18 -> 68564.636 | R17: =R3*W18 -> 76106.746 | S17: =S3*W18 -> 84478.488 | T17: =T3*W18 -> 93771.122
C18: % of Revenue | F18: =F17/F3 -> 0.050342971 | G18: =G17/G3 -> 0.057387839 | H18: =H17/H3 -> 0.06721352 | I18: =I17/I3 -> 0.057654571 | J18: =J17/J3 -> 0.060105803 | K18: =K17/K3 -> 0.1039724 | L18: =L17/L3 -> 0.12994921 | M18: =M17/M3 -> 0.12382705 | ... O18: =O17/O3 -> 0.13010084 | P18: 0.0872 | Q18: 0.0872 | R18: 0.0872 | S18: 0.0872 | T18: 0.0872 | V18: Average | W18: =AVERAGE(F18:O18) -> 0.087229112
C20: Change In NWC | F20: 2557 | G20: 3916 | H20: -173 | I20: -1043 | J20: -2438 | K20: 13481 | L20: -19611 | M20: -8148 | N20: -5876 | O20: -4648 | P20: 0 | Q20: 0 | R20: 0 | S20: 0 | T20: 0
C21: % of Revenue | F21: =F20/F3 -> 0.023895856 | G21: =G20/G3 -> 0.02879687 | H21: =H20/H3 -> -0.00097264233 | I21: =I20/I3 -> -0.0044785669 | J21: =J20/J3 -> -0.0086909405 | K21: =K20/K3 -> 0.034919081 | L21: =L20/L3 -> -0.04174134 | M21: =M20/M3 -> -0.015852664 | ... O21: =O20/O3 -> -0.0072857347 | P21: 0 | Q21: 0 | R21: 0 | S21: 0 | T21: 0 | V21: Average | W21: =AVERAGE(F21:O21) -> -0.00016330346
C23: Unlevered FCF | P23: =P12+P14-P17-P20 -> 46819.25 | Q23: =Q12+Q14-Q17-Q20 -> 51984.052 | R23: =R12+R14-R17-R20 -> 57716.982 | S23: =S12+S14-S17-S20 -> 64080.534 | T23: =T12+T14-T17-T20 -> 71144.077
C24: Present Value of FCF | P24: =P23/(1+'Valuation Assumptions'!I2)^1 -> 42914.605 | Q24: =Q23/(1+'Valuation Assumptions'!I2)^2 -> 43674.853 | R24: =R23/(1+'Valuation Assumptions'!I2)^3 -> 44447.322 | S24: =S23/(1+'Valuation Assumptions'!I2)^4 -> 45232.311 | T24: =T23/(1+'Valuation Assumptions'!I2)^5 -> 46030.116
C26: Terminal Value | T26: =T23*(1+'Valuation Assumptions'!D3)/('Valuation Assumptions'!I2-'Valuation Assumptions'!D3) -> 1105116.8
C27: Present Value of Terminal Value | T27: =T26/(1+'Valuation Assumptions'!I2)^5 -> 715008.98
C28: Enterprise Value | T28: =SUM(P24:T24)+T27 -> 937308.19
C29: Cash | T29: =78779+22423 -> 101202
C30: Debt | T30: 52623
C32: Equity Value | T32: =T28-(T30-T29) -> 985887.19
C33: Shares | T33: 10597.7
C34: Share Price | T34: =T32/T33 -> 93.028411
C36: Downside Case | F36: FY 2015 | G36: FY 2016 | H36: FY 2017 | I36: FY 2018 | J36: FY 2019 | K36: FY 2020 | L36: FY 2021 | M36: FY 2022 | N36: FY 2023 | O36: FY 2024 | P36: FY 2025 | Q36: FY 2026 | R36: FY 2027 | S36: FY 2028 | T36: FY 2029
C37: Revenue | F37: 107006 | G37: 135987 | H37: 177866 | I37: 232887 | J37: 280522 | K37: 386064 | L37: 469822 | M37: 513983 | N37: 574785 | O37: 637959 | P37: ='Exit Multiple'!M18 -> 663477.36 | Q37: ='Exit Multiple'!N18 -> 690016.45 | R37: ='Exit Multiple'!O18 -> 717617.11 | S37: ='Exit Multiple'!P18 -> 746321.8 | T37: ='Exit Multiple'!Q18 -> 776174.67
C38: % of Growth | G38: =(G37-F37)/F37 -> 0.27083528 | H38: =(H37-G37)/G37 -> 0.30796326 | I38: =(I37-H37)/H37 -> 0.30933962 | J38: =(J37-I37)/I37 -> 0.20454126 | K38: =(K37-J37)/J37 -> 0.37623431 | L38: =(L37-K37)/K37 -> 0.21695367 | M38: =(M37-L37)/L37 -> 0.093995173 | N38: =(N37-M37)/M37 -> 0.11829574 | ... T38: =(T37-S37)/S37 -> 0.04
C40: EBIT | F40: =F6 -> 2233 | G40: =G6 -> 4186 | H40: =H6 -> 4106 | I40: =I6 -> 12421 | J40: =J6 -> 14541 | K40: =K6 -> 22899 | L40: =L6 -> 24879 | M40: =M6 -> 12248 | ... O40: =O6 -> 68593 | P40: ='Exit Multiple'!M22 -> 32452.948 | Q40: ='Exit Multiple'!N22 -> 33751.066 | R40: ='Exit Multiple'!O22 -> 35101.109 | S40: ='Exit Multiple'!P22 -> 36505.153 | T40: ='Exit Multiple'!Q22 -> 37965.359
C41: % of Sales | F41: =F40/F37 -> 0.020867989 | G41: =G40/G37 -> 0.030782354 | H41: =H40/H37 -> 0.023084794 | I41: =I40/I37 -> 0.053334879 | J41: =J40/J37 -> 0.051835507 | K41: =K40/K37 -> 0.059314 | L41: =L40/L37 -> 0.052954098 | M41: =M40/M37 -> 0.023829582 | ... T41: =T40/T37 -> 0.048913422
C43: Taxes | F43: 950 | G43: 1425 | H43: 769 | I43: 1197 | J43: 2374 | K43: 2863 | L43: 4791 | M43: 3217 | N43: 7120 | O43: 9265 | P43: ='Exit Multiple'!M26 -> 5649.3692 | Q43: ='Exit Multiple'!N26 -> 5867.0158 | R43: ='Exit Multiple'!O26 -> 6093.3683 | S43: ='Exit Multiple'!P26 -> 6328.7749 | T43: ='Exit Multiple'!Q26 -> 6573.5977
C44: % of EBIT | F44: =F43/F40 -> 0.42543663 | G44: =G43/G40 -> 0.34042045 | H44: =H43/H40 -> 0.1872869 | I44: =I43/I40 -> 0.096369052 | J44: =J43/J40 -> 0.1632625 | K44: =K43/K40 -> 0.12502729 | L44: =L43/L40 -> 0.19257205 | M44: =M43/M40 -> 0.26265513 | ... T44: =T43/T40 -> 0.17314725
C46: EBIAT | F46: =F40-F43 -> 1283 | G46: =G40-G43 -> 2761 | H46: =H40-H43 -> 3337 | I46: =I40-I43 -> 11224 | J46: =J40-J43 -> 12167 | K46: =K40-K43 -> 20036 | L46: =L40-L43 -> 20088 | M46: =M40-M43 -> 9031 | ... T46: =T40-T43 -> 31391.762
C48: Depreciation | F48: 6281 | G48: 8116 | H48: 11478 | I48: 15341 | J48: 21789 | K48: 25180 | L48: 34433 | M48: 41921 | N48: 48663 | O48: 52795 | P48: =P37*W49 -> 47368.945 | Q48: =Q37*W49 -> 49263.702 | R48: =R37*W49 -> 51234.251 | S48: =S37*W49 -> 53283.621 | T48: =T37*W49 -> 55414.965
C49: % of Revenue | F49: =F48/F37 -> 0.058697643 | G49: =G48/G37 -> 0.059682176 | H49: =H48/H37 -> 0.064531726 | I49: =I48/I37 -> 0.065873149 | J49: =J48/J37 -> 0.077673052 | K49: =K48/K37 -> 0.065222347 | L49: =L48/L37 -> 0.073289459 | M49: =M48/M37 -> 0.081561063 | ... O49: =O48/O37 -> 0.082756102 | P49: 0.0714 | Q49: 0.0714 | R49: 0.0714 | S49: 0.0714 | T49: 0.0714 | V49: Average | W49: =AVERAGE(F49:O49) -> 0.071394968
C51: CapEx | F51: 5387 | G51: 7804 | H51: 11955 | I51: 13427 | J51: 16861 | K51: 40140 | L51: 61053 | M51: 63645 | N51: 52729 | O51: 82999 | P51: =P37*W52 -> 57874.541 | Q51: =Q37*W52 -> 60189.522 | R51: =R37*W52 -> 62597.103 | S51: =S37*W52 -> 65100.987 | T51: =T37*W52 -> 67705.027
C52: % of Revenue | F52: =F51/F37 -> 0.050342971 | G52: =G51/G37 -> 0.057387839 | H52: =H51/H37 -> 0.06721352 | I52: =I51/I37 -> 0.057654571 | J52: =J51/J37 -> 0.060105803 | K52: =K51/K37 -> 0.1039724 | L52: =L51/L37 -> 0.12994921 | M52: =M51/M37 -> 0.12382705 | ... O52: =O51/O37 -> 0.13010084 | P52: 0.0872 | Q52: 0.0872 | R52: 0.0872 | S52: 0.0872 | T52: 0.0872 | V52: Average | W52: =AVERAGE(F52:O52) -> 0.087229112
C54: Change In NWC | F54: 2557 | G54: 3916 | H54: -173 | I54: -1043 | J54: -2438 | K54: 13481 | L54: -19611 | M54: -8148 | N54: -5876 | O54: -4648 | P54: 0 | Q54: 0 | R54: 0 | S54: 0 | T54: 0
C55: % of Revenue | F55: =F54/F37 -> 0.023895856 | G55: =G54/G37 -> 0.02879687 | H55: =H54/H37 -> -0.00097264233 | I55: =I54/I37 -> -0.0044785669 | J55: =J54/J37 -> -0.0086909405 | K55: =K54/K37 -> 0.034919081 | L55: =L54/L37 -> -0.04174134 | M55: =M54/M37 -> -0.015852664 | ... O55: =O54/O37 -> -0.0072857347 | P55: 0 | Q55: 0 | R55: 0 | S55: 0 | T55: 0 | V55: Average | W55: =AVERAGE(F55:O55) -> -0.00016330346
C57: Unlevered FCF | P57: =P46+P48-P51-P54 -> 16297.983 | Q57: =Q46+Q48-Q51-Q54 -> 16958.23 | R57: =R46+R48-R51-R54 -> 17644.888 | S57: =S46+S48-S51-S54 -> 18359.012 | T57: =T46+T48-T51-T54 -> 19101.7
C58: Present Value of FCF | P58: =P57/(1+'Valuation Assumptions'!I2)^1 -> 14938.759 | Q58: =Q57/(1+'Valuation Assumptions'!I2)^2 -> 14247.605 | R58: =R57/(1+'Valuation Assumptions'!I2)^3 -> 13588.168 | S58: =S57/(1+'Valuation Assumptions'!I2)^4 -> 12959.014 | T58: =T57/(1+'Valuation Assumptions'!I2)^5 -> 12358.773
...

Sheet Exit Multiple
A2: Upside Case (In Millions) | C2: FY 2015 | D2: FY 2016 | E2: FY 2017 | F2: FY 2018 | G2: FY 2019 | H2: FY 2020 | I2: FY 2021 | J2: FY 2022 | K2: FY 2023 | L2: FY 2024 | M2: FY 2025 | N2: FY 2026 | O2: FY 2027 | P2: FY 2028 | Q2: FY 2029 | V2: Exit Multiple Method (P/E applied to FY2029 Net Income)
A3: Total Revenue (or Net Sales) | B3: SALES_REV_TURN | C3: 107006 | D3: 135987 | E3: 177866 | F3: 232887 | G3: 280522 | H3: 386064 | I3: 469822 | J3: 513983 | K3: 574785 | L3: 637959 | M3: ='Valuation Assumptions'!V4 -> 708134.49 | N3: ='Valuation Assumptions'!W4 -> 786029.28 | O3: ='Valuation Assumptions'!X4 -> 872492.51 | P3: ='Valuation Assumptions'!Y4 -> 968466.68 | Q3: ='Valuation Assumptions'!Z4 -> 1074998 | R3: =RATE(5,0,-L3,Q3) -> 0.11 | S3: 5yr Compound Annual Growth Rate | V3: PV(Market Cap) | W3: =Q13/(1+'Valuation Assumptions'!I2)^5 -> 2014538.9
A4: Cost of Revenue | B4: IS_COGS_TO_FE_AND_PP_AND_G | C4: 71651 | D4: 88265 | E4: 111934 | F4: 139156 | G4: 165536 | H4: 233307 | I4: 272344 | J4: 288831 | K4: 304739 | L4: 326288 | M4: =M3*$R4 -> 362179.68 | N4: =N3*$R4 -> 402019.44 | O4: =O3*$R4 -> 446241.58 | P4: =P3*$R4 -> 495328.16 | Q4: =Q3*$R4 -> 549814.26 | R4: =MIN(SUM(H4:L4)/SUM(H3:L3),SUM(J4:L4)/SUM(J3:L3),L4/L3) -> 0.51145607 | S4: % of Revenue | V4: Share Price Today | W4: =W3/DCF!T33 -> 190.09209
A5: SG&A | B5: IS_SGA_EXPENSE | C5: 7001 | D5: 9665 | E5: 13743 | F5: 18150 | G5: 24081 | H5: 28676 | I5: 41374 | J5: 54129 | K5: 56186 | L5: 55266 | M5: =M3*$R5 -> 61345.26 | N5: =N3*$R5 -> 68093.239 | O5: =O3*$R5 -> 75583.495 | P5: =P3*$R5 -> 83897.679 | Q5: =Q3*$R5 -> 93126.424 | R5: =MIN(SUM(H5:L5)/SUM(H3:L3), SUM(J5:L5)/SUM(J3:L3), L5/L3) -> 0.086629392 | S5: % of Revenue
A6: Other Operating Expenses | C6: 26121 | D6: 33871 | E6: 48083 | F6: 63160 | G6: 76364 | H6: 101182 | I6: 131225 | J6: 158775 | K6: 177008 | L6: 187812 | M6: =M3*$R6 -> 214727.45 | N6: =N3*$R6 -> 238347.46 | O6: =O3*$R6 -> 264565.69 | P6: =P3*$R6 -> 293667.91 | Q6: =Q3*$R6 -> 325971.38 | R6: =SUM(J6:L6)/SUM(J3:L3) -> 0.30322975 | S6: % of Revenue over Last 3 years
A7: Operating Income | B7: IS_OPER_INC | C7: 2233 | D7: 4186 | E7: 4106 | F7: 12421 | G7: 14541 | H7: 22899 | I7: 24879 | J7: 12248 | K7: 36852 | L7: 68593 | M7: =M3-SUM(M4:M6) -> 69882.104 | N7: =N3-SUM(N4:N6) -> 77569.136 | O7: =O3-SUM(O4:O6) -> 86101.741 | P7: =P3-SUM(P4:P6) -> 95572.932 | Q7: =Q3-SUM(Q4:Q6) -> 106085.95 | R7: =SUM(M7:Q7)/SUM(M3:Q3) -> 0.098684791 | S7: 5yr Average Operating Margin
A8: Interest Expense, Net | B8: IS_NET_INTEREST_EXPENSE | C8: 409 | D8: 384 | E8: 646 | F8: 977 | G8: 768 | H8: 1092 | I8: 1361 | J8: 1378 | K8: 233 | L8: -2271 | M8: =AVERAGE(K8:L8) -> -1019 | N8: =M8 -> -1019 | O8: =N8 -> -1019 | P8: =O8 -> -1019 | Q8: =P8 -> -1019 | S8: Average of Last 2 years
A9: Other Non-Operating Income / (Losses) | C9: -256 | D9: 90 | E9: 346 | F9: -183 | G9: 203 | H9: 2371 | I9: 14633 | J9: -16806 | K9: 938 | L9: -2250 | M9: =AVERAGE(H9:L9) -> -222.8 | N9: =M9 -> -222.8 | O9: =N9 -> -222.8 | P9: =O9 -> -222.8 | Q9: =P9 -> -222.8 | S9: Average of Last 5 years
A10: Pretax Income | B10: PRETAX_INC | C10: 1568 | D10: 3892 | E10: 3806 | F10: 11261 | G10: 13976 | H10: 24178 | I10: 38151 | J10: -5936 | K10: 37557 | L10: 68614 | M10: =M7-M8+M9 -> 70678.304 | N10: =N7-N8+N9 -> 78365.336 | O10: =O7-O8+O9 -> 86897.941 | P10: =P7-P8+P9 -> 96369.132 | Q10: =Q7-Q8+Q9 -> 106882.15 | R10: =SUM(M10:Q10)/SUM(M$3:Q$3) -> 0.099587487 | S10: 5yr Average Pretax Margin
A11: Taxes | B11: IS_INC_TAX_EXP | C11: 950 | D11: 1425 | E11: 769 | F11: 1197 | G11: 2374 | H11: 2863 | I11: 4791 | J11: 3217 | K11: 7120 | L11: 9265 | M11: =M10*$R11 -> 11850.15 | N11: =N10*$R11 -> 13138.983 | O11: =O10*$R11 -> 14569.587 | P11: =P10*$R11 -> 16157.557 | Q11: =Q10*$R11 -> 17920.204 | R11: =MAX(SUM(H11:L11)/SUM(H10:L10),L11/L10) -> 0.1676632 | S11: % of Pretax Income
A12: Net Income after Taxes | B12: NET_INCOME | C12: 596 | D12: 2371 | E12: 3033 | F12: 10073 | G12: 11588 | H12: 21331 | I12: 33364 | J12: -2722 | K12: 30425 | L12: 59248 | M12: =M10-M11 -> 58828.154 | N12: =N10-N11 -> 65226.353 | O12: =O10-O11 -> 72328.354 | P12: =P10-P11 -> 80211.575 | Q12: =Q10-Q11 -> 88961.951 | R12: =SUM(M12:Q12)/SUM(M$3:Q$3) -> 0.082890331 | S12: 5yr Average Net Income Margin
A13: Market Capitalization (Value) as of Today | B13: HISTORICAL_MARKET_CAP | C13: 318344.19 | D13: 357687.99 | E13: 566023.48 | F13: 737467.27 | G13: 920224.32 | H13: 1638235.8 | I13: 1697179.1 | J13: 860328 | K13: 1577593 | L13: 2323998.3 | Q13: =Q12*Q14 -> 3113668.3
A14: Price to Earnings Multiple | C14: =IF(C13/C12<0,"NA",C13/C12) -> 534.13455 | D14: =IF(D13/D12<0,"NA",D13/D12) -> 150.85955 | E14: =IF(E13/E12<0,"NA",E13/E12) -> 186.62166 | F14: =IF(F13/F12<0,"NA",F13/F12) -> 73.212277 | G14: =IF(G13/G12<0,"NA",G13/G12) -> 79.411833 | H14: =IF(H13/H12<0,"NA",H13/H12) -> 76.800703 | I14: =IF(I13/I12<0,"NA",I13/I12) -> 50.868573 | J14: =IF(J13/J12<0,"NA",J13/J12) -> NA | ... L14: =IF(L13/L12<0,"NA",L13/L12) -> 39.224924 | Q14: ='Valuation Assumptions'!D10 -> 35
A17: Downside Case (In Millions) | C17: =C2 -> FY 2015 | D17: =D2 -> FY 2016 | E17: =E2 -> FY 2017 | F17: =F2 -> FY 2018 | G17: =G2 -> FY 2019 | H17: =H2 -> FY 2020 | I17: =I2 -> FY 2021 | J17: =J2 -> FY 2022 | ... Q17: =Q2 -> FY 2029
A18: Total Revenue (or Net Sales) | B18: SALES_REV_TURN | C18: =C3 -> 107006 | D18: =D3 -> 135987 | E18: =E3 -> 177866 | F18: =F3 -> 232887 | G18: =G3 -> 280522 | H18: =H3 -> 386064 | I18: =I3 -> 469822 | J18: =J3 -> 513983 | ... L18: =L3 -> 637959 | M18: ='Valuation Assumptions'!V5 -> 663477.36 | N18: ='Valuation Assumptions'!W5 -> 690016.45 | O18: ='Valuation Assumptions'!X5 -> 717617.11 | P18: ='Valuation Assumptions'!Y5 -> 746321.8 | Q18: ='Valuation Assumptions'!Z5 -> 776174.67 | R18: =RATE(5,0,-L18,Q18) -> 0.04 | S18: 5yr Compound Annual Growth Rate | V18: PV(Market Cap) | W18: =Q28/(1+'Valuation Assumptions'!I2)^5 -> 527846.69
A19: Cost of Revenue | B19: IS_COGS_TO_FE_AND_PP_AND_G | C19: =C4 -> 71651 | D19: =D4 -> 88265 | E19: =E4 -> 111934 | F19: =F4 -> 139156 | G19: =G4 -> 165536 | H19: =H4 -> 233307 | I19: =I4 -> 272344 | J19: =J4 -> 288831 | ... L19: =L4 -> 326288 | M19: =M18*$R19 -> 366215.51 | N19: =N18*$R19 -> 380864.13 | O19: =O18*$R19 -> 396098.7 | P19: =P18*$R19 -> 411942.65 | Q19: =Q18*$R19 -> 428420.35 | R19: =MAX(SUM(H19:L19)/SUM(H18:L18),SUM(J19:L19)/SUM(J18:L18),L4/L3) -> 0.55196384 | S19: % of Revenue | V19: Share Price Today | W19: =W18/DCF!T33 -> 49.807665
A20: SG&A | B20: IS_SGA_EXPENSE | C20: =C5 -> 7001 | D20: =D5 -> 9665 | E20: =E5 -> 13743 | F20: =F5 -> 18150 | G20: =G5 -> 24081 | H20: =H5 -> 28676 | I20: =I5 -> 41374 | J20: =J5 -> 54129 | ... L20: =L5 -> 55266 | M20: =M18*$R20 -> 63622.822 | N20: =N18*$R20 -> 66167.735 | O20: =O18*$R20 -> 68814.444 | P20: =P18*$R20 -> 71567.022 | Q20: =Q18*$R20 -> 74429.703 | R20: =MAX(SUM(H20:L20)/SUM(H18:L18), SUM(J20:L20)/SUM(J18:L18), L20/L18) -> 0.095892981
A21: Other Operating Expenses | C21: =C6 -> 26121 | D21: =D6 -> 33871 | E21: =E6 -> 48083 | F21: =F6 -> 63160 | G21: =G6 -> 76364 | H21: =H6 -> 101182 | I21: =I6 -> 131225 | J21: =J6 -> 158775 | ... L21: =L6 -> 187812 | M21: =M18*$R21 -> 201186.08 | N21: =N18*$R21 -> 209233.52 | O21: =O18*$R21 -> 217602.86 | P21: =P18*$R21 -> 226306.97 | Q21: =Q18*$R21 -> 235359.25 | R21: =SUM(J21:L21)/SUM(J18:L18) -> 0.30322975 | S21: % of Revenue over Last 3 years
A22: Operating Income | B22: IS_OPER_INC | C22: =C7 -> 2233 | D22: =D7 -> 4186 | E22: =E7 -> 4106 | F22: =F7 -> 12421 | G22: =G7 -> 14541 | H22: =H7 -> 22899 | I22: =I7 -> 24879 | J22: =J7 -> 12248 | ... L22: =L7 -> 68593 | M22: =M18-SUM(M19:M21) -> 32452.948 | N22: =N18-SUM(N19:N21) -> 33751.066 | O22: =O18-SUM(O19:O21) -> 35101.109 | P22: =P18-SUM(P19:P21) -> 36505.153 | Q22: =Q18-SUM(Q19:Q21) -> 37965.359 | R22: =SUM(M22:Q22)/SUM(M18:Q18) -> 0.048913422 | S22: 5yr Average Operating Margin
A23: Interest Expense, Net | B23: IS_NET_INTEREST_EXPENSE | C23: =C8 -> 409 | D23: =D8 -> 384 | E23: =E8 -> 646 | F23: =F8 -> 977 | G23: =G8 -> 768 | H23: =H8 -> 1092 | I23: =I8 -> 1361 | J23: =J8 -> 1378 | ... L23: =L8 -> -2271 | M23: =AVERAGE(K23:L23) -> -1019 | N23: =M23 -> -1019 | O23: =N23 -> -1019 | P23: =O23 -> -1019 | Q23: =P23 -> -1019 | S23: Avg of Last 2 years
A24: Other Non-Operating Income / (Losses) | C24: =C9 -> -256 | D24: =D9 -> 90 | E24: =E9 -> 346 | F24: =F9 -> -183 | G24: =G9 -> 203 | H24: =H9 -> 2371 | I24: =I9 -> 14633 | J24: =J9 -> -16806 | ... L24: =L9 -> -2250 | M24: =AVERAGE(H24:L24) -> -222.8 | N24: =M24 -> -222.8 | O24: =N24 -> -222.8 | P24: =O24 -> -222.8 | Q24: =P24 -> -222.8 | S24: Average of Last 5 years
A25: Pretax Income | B25: PRETAX_INC | C25: =C10 -> 1568 | D25: =D10 -> 3892 | E25: =E10 -> 3806 | F25: =F10 -> 11261 | G25: =G10 -> 13976 | H25: =H10 -> 24178 | I25: =I10 -> 38151 | J25: =J10 -> -5936 | ... L25: =L10 -> 68614 | M25: =M22-SUM(M23:M24) -> 33694.748 | N25: =N22-SUM(N23:N24) -> 34992.866 | O25: =O22-SUM(O23:O24) -> 36342.909 | P25: =P22-SUM(P23:P24) -> 37746.953 | Q25: =Q22-SUM(Q23:Q24) -> 39207.159 | R25: =SUM(M25:Q25)/SUM(M18:Q18) -> 0.050641213 | S25: 5yr Average Pretax Margin
A26: Taxes | B26: IS_INC_TAX_EXP | C26: =C11 -> 950 | D26: =D11 -> 1425 | E26: =E11 -> 769 | F26: =F11 -> 1197 | G26: =G11 -> 2374 | H26: =H11 -> 2863 | I26: =I11 -> 4791 | J26: =J11 -> 3217 | ... L26: =L11 -> 9265 | M26: =M25*$R26 -> 5649.3692 | N26: =N25*$R26 -> 5867.0158 | O26: =O25*$R26 -> 6093.3683 | P26: =P25*$R26 -> 6328.7749 | Q26: =Q25*$R26 -> 6573.5977 | R26: =MAX(SUM(H26:L26)/SUM(H25:L25),L26/L25) -> 0.1676632 | S26: % of Pretax Income
A27: Net Income after Taxes | B27: NET_INCOME | C27: =C12 -> 596 | D27: =D12 -> 2371 | E27: =E12 -> 3033 | F27: =F12 -> 10073 | G27: =G12 -> 11588 | H27: =H12 -> 21331 | I27: =I12 -> 33364 | J27: =J12 -> -2722 | ... L27: =L12 -> 59248 | M27: =M25-M26 -> 28045.379 | N27: =N25-N26 -> 29125.85 | O27: =O25-O26 -> 30249.541 | P27: =P25-P26 -> 31418.178 | Q27: =Q25-Q26 -> 32633.562 | R27: =SUM(M27:Q27)/SUM(M18:Q18) -> 0.042150545 | S27: 5yr Average Net Income Margin
A28: Market Capitalization (Value) as of Today | B28: HISTORICAL_MARKET_CAP | C28: =C13 -> 318344.19 | D28: =D13 -> 357687.99 | E28: =E13 -> 566023.48 | F28: =F13 -> 737467.27 | G28: =G13 -> 920224.32 | H28: =H13 -> 1638235.8 | I28: =I13 -> 1697179.1 | J28: =J13 -> 860328 | ... L28: =L13 -> 2323998.3 | Q28: =Q27*Q29 -> 815839.04
A29: Price to Earnings Multiple | C29: =C14 -> 534.13455 | D29: =D14 -> 150.85955 | E29: =E14 -> 186.62166 | F29: =F14 -> 73.212277 | G29: =G14 -> 79.411833 | H29: =H14 -> 76.800703 | I29: =I14 -> 50.868573 | J29: =J14 -> NA | ... L29: =L14 -> 39.224924 | Q29: ='Valuation Assumptions'!D11 -> 25

Sheet Valuation Outputs
C2: Upside | D2: Downside
B3: DCF | C3: =DCF!T34 -> 93.028411 | D3: =DCF!T68 -> 29.1239
B4: Exit Multiple | C4: ='Exit Multiple'!W4 -> 190.09209 | D4: ='Exit Multiple'!W19 -> 49.807665
